[2025-07-15T10:21:24.106+0000] {local_task_job_runner.py:120} INFO - ::group::Pre task execution logs
[2025-07-15T10:21:24.118+0000] {taskinstance.py:2076} INFO - Dependencies all met for dep_context=non-requeueable deps ti=<TaskInstance: run_dbt_models.dbt_run manual__2025-07-15T10:21:20.603554+00:00 [queued]>
[2025-07-15T10:21:24.124+0000] {taskinstance.py:2076} INFO - Dependencies all met for dep_context=requeueable deps ti=<TaskInstance: run_dbt_models.dbt_run manual__2025-07-15T10:21:20.603554+00:00 [queued]>
[2025-07-15T10:21:24.125+0000] {taskinstance.py:2306} INFO - Starting attempt 1 of 1
[2025-07-15T10:21:24.136+0000] {taskinstance.py:2330} INFO - Executing <Task(BashOperator): dbt_run> on 2025-07-15 10:21:20.603554+00:00
[2025-07-15T10:21:24.140+0000] {standard_task_runner.py:63} INFO - Started process 493 to run task
[2025-07-15T10:21:24.143+0000] {standard_task_runner.py:90} INFO - Running: ['airflow', 'tasks', 'run', 'run_dbt_models', 'dbt_run', 'manual__2025-07-15T10:21:20.603554+00:00', '--job-id', '11', '--raw', '--subdir', 'DAGS_FOLDER/run_dbt.py', '--cfg-path', '/tmp/tmp0monvx_z']
[2025-07-15T10:21:24.144+0000] {standard_task_runner.py:91} INFO - Job 11: Subtask dbt_run
[2025-07-15T10:21:24.183+0000] {task_command.py:426} INFO - Running <TaskInstance: run_dbt_models.dbt_run manual__2025-07-15T10:21:20.603554+00:00 [running]> on host ZeeLaptop.localdomain
[2025-07-15T10:21:24.289+0000] {taskinstance.py:2648} INFO - Exporting env vars: AIRFLOW_CTX_DAG_OWNER='airflow' AIRFLOW_CTX_DAG_ID='run_dbt_models' AIRFLOW_CTX_TASK_ID='dbt_run' AIRFLOW_CTX_EXECUTION_DATE='2025-07-15T10:21:20.603554+00:00' AIRFLOW_CTX_TRY_NUMBER='1' AIRFLOW_CTX_DAG_RUN_ID='manual__2025-07-15T10:21:20.603554+00:00'
[2025-07-15T10:21:24.290+0000] {taskinstance.py:430} INFO - ::endgroup::
[2025-07-15T10:21:24.291+0000] {subprocess.py:63} INFO - Tmp dir root location: /tmp
[2025-07-15T10:21:24.292+0000] {subprocess.py:75} INFO - Running command: ['/usr/bin/bash', '-c', '\n        cd /home/reach2zeeshan/clinicaltrials &&\n        /home/reach2zeeshan/clinicaltrials/venv/bin/dbt run\n        ']
[2025-07-15T10:21:24.298+0000] {subprocess.py:86} INFO - Output:
[2025-07-15T10:21:26.675+0000] {subprocess.py:93} INFO - [0m10:21:26  Running with dbt=1.10.4
[2025-07-15T10:21:27.374+0000] {subprocess.py:93} INFO - [0m10:21:27  Registered adapter: snowflake=1.10.0
[2025-07-15T10:21:27.852+0000] {subprocess.py:93} INFO - [0m10:21:27  Found 2 models, 2 data tests, 1 source, 743 macros
[2025-07-15T10:21:27.855+0000] {subprocess.py:93} INFO - [0m10:21:27
[2025-07-15T10:21:27.855+0000] {subprocess.py:93} INFO - [0m10:21:27  Concurrency: 1 threads (target='dev')
[2025-07-15T10:21:27.855+0000] {subprocess.py:93} INFO - [0m10:21:27
[2025-07-15T10:21:30.771+0000] {subprocess.py:93} INFO - [0m10:21:30  1 of 2 START sql table model sh_clinical_trials_gov_stage.stg_ctgov__studies ... [RUN]
[2025-07-15T10:21:31.170+0000] {subprocess.py:93} INFO - [0m10:21:31  1 of 2 ERROR creating sql table model sh_clinical_trials_gov_stage.stg_ctgov__studies  [[31mERROR[0m in 0.39s]
[2025-07-15T10:21:31.174+0000] {subprocess.py:93} INFO - [0m10:21:31  2 of 2 SKIP relation sh_clinical_trials_gov_cur.int_sponsor_summary ............ [[33mSKIP[0m]
[2025-07-15T10:21:31.703+0000] {subprocess.py:93} INFO - [0m10:21:31
[2025-07-15T10:21:31.704+0000] {subprocess.py:93} INFO - [0m10:21:31  Finished running 2 table models in 0 hours 0 minutes and 3.85 seconds (3.85s).
[2025-07-15T10:21:31.742+0000] {subprocess.py:93} INFO - [0m10:21:31
[2025-07-15T10:21:31.742+0000] {subprocess.py:93} INFO - [0m10:21:31  [31mCompleted with 1 error, 0 partial successes, and 0 warnings:[0m
[2025-07-15T10:21:31.742+0000] {subprocess.py:93} INFO - [0m10:21:31
[2025-07-15T10:21:31.743+0000] {subprocess.py:93} INFO - [0m10:21:31  [31mFailure in model stg_ctgov__studies (models/stage/stg_ctgov__studies.sql)[0m
[2025-07-15T10:21:31.743+0000] {subprocess.py:93} INFO - [0m10:21:31    Database Error in model stg_ctgov__studies (models/stage/stg_ctgov__studies.sql)
[2025-07-15T10:21:31.743+0000] {subprocess.py:93} INFO -   002003 (42S02): SQL compilation error:
[2025-07-15T10:21:31.743+0000] {subprocess.py:93} INFO -   Object 'DB_CLINICAL_TRIALS_GOV.SH_CLINICAL_TRIALS_GOV_RAW.RAW_CTGOV__STUDIES' does not exist or not authorized.
[2025-07-15T10:21:31.744+0000] {subprocess.py:93} INFO -   compiled code at target/run/clinicaltrials/models/stage/stg_ctgov__studies.sql
[2025-07-15T10:21:31.744+0000] {subprocess.py:93} INFO - [0m10:21:31
[2025-07-15T10:21:31.744+0000] {subprocess.py:93} INFO - [0m10:21:31    compiled code at target/compiled/clinicaltrials/models/stage/stg_ctgov__studies.sql
[2025-07-15T10:21:31.744+0000] {subprocess.py:93} INFO - [0m10:21:31
[2025-07-15T10:21:31.745+0000] {subprocess.py:93} INFO - [0m10:21:31  Done. PASS=0 WARN=0 ERROR=1 SKIP=1 NO-OP=0 TOTAL=2
[2025-07-15T10:21:33.070+0000] {subprocess.py:97} INFO - Command exited with return code 1
[2025-07-15T10:21:33.071+0000] {taskinstance.py:441} INFO - ::group::Post task execution logs
[2025-07-15T10:21:33.079+0000] {taskinstance.py:2905} ERROR - Task failed with exception
Traceback (most recent call last):
  File "/home/reach2zeeshan/clinicaltrials/venv/lib/python3.12/site-packages/airflow/models/taskinstance.py", line 465, in _execute_task
    result = _execute_callable(context=context, **execute_callable_kwargs)
             ^^^^^^^^^^^^^^^^^^^^^^^^^^^^^^^^^^^^^^^^^^^^^^^^^^^^^^^^^^^^^
  File "/home/reach2zeeshan/clinicaltrials/venv/lib/python3.12/site-packages/airflow/models/taskinstance.py", line 432, in _execute_callable
    return execute_callable(context=context, **execute_callable_kwargs)
           ^^^^^^^^^^^^^^^^^^^^^^^^^^^^^^^^^^^^^^^^^^^^^^^^^^^^^^^^^^^^
  File "/home/reach2zeeshan/clinicaltrials/venv/lib/python3.12/site-packages/airflow/models/baseoperator.py", line 400, in wrapper
    return func(self, *args, **kwargs)
           ^^^^^^^^^^^^^^^^^^^^^^^^^^^
  File "/home/reach2zeeshan/clinicaltrials/venv/lib/python3.12/site-packages/airflow/operators/bash.py", line 243, in execute
    raise AirflowException(
airflow.exceptions.AirflowException: Bash command failed. The command returned a non-zero exit code 1.
[2025-07-15T10:21:33.085+0000] {taskinstance.py:1206} INFO - Marking task as FAILED. dag_id=run_dbt_models, task_id=dbt_run, run_id=manual__2025-07-15T10:21:20.603554+00:00, execution_date=20250715T102120, start_date=20250715T102124, end_date=20250715T102133
[2025-07-15T10:21:33.097+0000] {standard_task_runner.py:110} ERROR - Failed to execute job 11 for task dbt_run (Bash command failed. The command returned a non-zero exit code 1.; 493)
[2025-07-15T10:21:33.137+0000] {local_task_job_runner.py:240} INFO - Task exited with return code 1
[2025-07-15T10:21:33.151+0000] {taskinstance.py:3498} INFO - 0 downstream tasks scheduled from follow-on schedule check
[2025-07-15T10:21:33.160+0000] {local_task_job_runner.py:222} INFO - ::endgroup::
