[2025-07-15T10:26:19.436+0000] {task_context_logger.py:104} ERROR - Executor reports task instance <TaskInstance: run_dbt_models.dbt_run manual__2025-07-15T10:21:20.603554+00:00 [queued]> finished (failed) although the task says it's queued. (Info: None) Was the task killed externally?
