[2025-07-15T11:03:20.979+0000] {local_task_job_runner.py:120} INFO - ::group::Pre task execution logs
[2025-07-15T11:03:20.989+0000] {taskinstance.py:2076} INFO - Dependencies all met for dep_context=non-requeueable deps ti=<TaskInstance: run_dbt_models.ingest_data manual__2025-07-15T10:50:45.194882+00:00 [queued]>
[2025-07-15T11:03:20.994+0000] {taskinstance.py:2076} INFO - Dependencies all met for dep_context=requeueable deps ti=<TaskInstance: run_dbt_models.ingest_data manual__2025-07-15T10:50:45.194882+00:00 [queued]>
[2025-07-15T11:03:20.995+0000] {taskinstance.py:2306} INFO - Starting attempt 5 of 5
[2025-07-15T11:03:21.067+0000] {taskinstance.py:2330} INFO - Executing <Task(BashOperator): ingest_data> on 2025-07-15 10:50:45.194882+00:00
[2025-07-15T11:03:21.072+0000] {standard_task_runner.py:63} INFO - Started process 2833 to run task
[2025-07-15T11:03:21.074+0000] {standard_task_runner.py:90} INFO - Running: ['airflow', 'tasks', 'run', 'run_dbt_models', 'ingest_data', 'manual__2025-07-15T10:50:45.194882+00:00', '--job-id', '20', '--raw', '--subdir', 'DAGS_FOLDER/run_dbt.py', '--cfg-path', '/tmp/tmphvcnc7er']
[2025-07-15T11:03:21.076+0000] {standard_task_runner.py:91} INFO - Job 20: Subtask ingest_data
[2025-07-15T11:03:21.112+0000] {task_command.py:426} INFO - Running <TaskInstance: run_dbt_models.ingest_data manual__2025-07-15T10:50:45.194882+00:00 [running]> on host ZeeLaptop.localdomain
[2025-07-15T11:03:21.163+0000] {taskinstance.py:2648} INFO - Exporting env vars: AIRFLOW_CTX_DAG_OWNER='airflow' AIRFLOW_CTX_DAG_ID='run_dbt_models' AIRFLOW_CTX_TASK_ID='ingest_data' AIRFLOW_CTX_EXECUTION_DATE='2025-07-15T10:50:45.194882+00:00' AIRFLOW_CTX_TRY_NUMBER='5' AIRFLOW_CTX_DAG_RUN_ID='manual__2025-07-15T10:50:45.194882+00:00'
[2025-07-15T11:03:21.165+0000] {taskinstance.py:430} INFO - ::endgroup::
[2025-07-15T11:03:21.165+0000] {subprocess.py:63} INFO - Tmp dir root location: /tmp
[2025-07-15T11:03:21.166+0000] {subprocess.py:75} INFO - Running command: ['/usr/bin/bash', '-c', '\n        /home/reach2zeeshan/clinicaltrials/venv/bin/python /home/reach2zeeshan/clinicaltrials/ingestion/data_ingestion.py\n        ']
[2025-07-15T11:03:21.175+0000] {subprocess.py:86} INFO - Output:
[2025-07-15T11:03:32.530+0000] {subprocess.py:93} INFO - Fetching studies…
[2025-07-15T11:03:32.530+0000] {subprocess.py:93} INFO - Total fetched: 458 records.
[2025-07-15T11:03:32.531+0000] {subprocess.py:93} INFO - Loading into Snowflake…
[2025-07-15T11:03:32.531+0000] {subprocess.py:93} INFO - Traceback (most recent call last):
[2025-07-15T11:03:32.531+0000] {subprocess.py:93} INFO -   File "/home/reach2zeeshan/clinicaltrials/ingestion/data_ingestion.py", line 94, in <module>
[2025-07-15T11:03:32.531+0000] {subprocess.py:93} INFO -     main()
[2025-07-15T11:03:32.532+0000] {subprocess.py:93} INFO -   File "/home/reach2zeeshan/clinicaltrials/ingestion/data_ingestion.py", line 91, in main
[2025-07-15T11:03:32.532+0000] {subprocess.py:93} INFO -     load_to_snowflake(studies)
[2025-07-15T11:03:32.532+0000] {subprocess.py:93} INFO -   File "/home/reach2zeeshan/clinicaltrials/ingestion/data_ingestion.py", line 69, in load_to_snowflake
[2025-07-15T11:03:32.532+0000] {subprocess.py:93} INFO -     cur.execute(f"TRUNCATE TABLE {TABLE_NAME}")
[2025-07-15T11:03:32.532+0000] {subprocess.py:93} INFO -   File "/home/reach2zeeshan/clinicaltrials/venv/lib/python3.12/site-packages/snowflake/connector/cursor.py", line 1137, in execute
[2025-07-15T11:03:32.533+0000] {subprocess.py:93} INFO -     Error.errorhandler_wrapper(self.connection, self, error_class, errvalue)
[2025-07-15T11:03:32.533+0000] {subprocess.py:93} INFO -   File "/home/reach2zeeshan/clinicaltrials/venv/lib/python3.12/site-packages/snowflake/connector/errors.py", line 279, in errorhandler_wrapper
[2025-07-15T11:03:32.533+0000] {subprocess.py:93} INFO -     handed_over = Error.hand_to_other_handler(
[2025-07-15T11:03:32.534+0000] {subprocess.py:93} INFO -                   ^^^^^^^^^^^^^^^^^^^^^^^^^^^^
[2025-07-15T11:03:32.534+0000] {subprocess.py:93} INFO -   File "/home/reach2zeeshan/clinicaltrials/venv/lib/python3.12/site-packages/snowflake/connector/errors.py", line 334, in hand_to_other_handler
[2025-07-15T11:03:32.534+0000] {subprocess.py:93} INFO -     cursor.errorhandler(connection, cursor, error_class, error_value)
[2025-07-15T11:03:32.534+0000] {subprocess.py:93} INFO -   File "/home/reach2zeeshan/clinicaltrials/venv/lib/python3.12/site-packages/snowflake/connector/errors.py", line 210, in default_errorhandler
[2025-07-15T11:03:32.534+0000] {subprocess.py:93} INFO -     raise error_class(
[2025-07-15T11:03:32.535+0000] {subprocess.py:93} INFO - snowflake.connector.errors.ProgrammingError: 002003 (42S02): SQL compilation error:
[2025-07-15T11:03:32.535+0000] {subprocess.py:93} INFO - Table 'DB_CLINICAL_TRIALS_GOV.SH_CLINICAL_TRIALS_GOV_RAW.RAW_CTGOV__STUDIES' does not exist or not authorized.
[2025-07-15T11:03:32.688+0000] {subprocess.py:97} INFO - Command exited with return code 1
[2025-07-15T11:03:32.689+0000] {taskinstance.py:441} INFO - ::group::Post task execution logs
[2025-07-15T11:03:32.693+0000] {taskinstance.py:2905} ERROR - Task failed with exception
Traceback (most recent call last):
  File "/home/reach2zeeshan/clinicaltrials/venv/lib/python3.12/site-packages/airflow/models/taskinstance.py", line 465, in _execute_task
    result = _execute_callable(context=context, **execute_callable_kwargs)
             ^^^^^^^^^^^^^^^^^^^^^^^^^^^^^^^^^^^^^^^^^^^^^^^^^^^^^^^^^^^^^
  File "/home/reach2zeeshan/clinicaltrials/venv/lib/python3.12/site-packages/airflow/models/taskinstance.py", line 432, in _execute_callable
    return execute_callable(context=context, **execute_callable_kwargs)
           ^^^^^^^^^^^^^^^^^^^^^^^^^^^^^^^^^^^^^^^^^^^^^^^^^^^^^^^^^^^^
  File "/home/reach2zeeshan/clinicaltrials/venv/lib/python3.12/site-packages/airflow/models/baseoperator.py", line 400, in wrapper
    return func(self, *args, **kwargs)
           ^^^^^^^^^^^^^^^^^^^^^^^^^^^
  File "/home/reach2zeeshan/clinicaltrials/venv/lib/python3.12/site-packages/airflow/operators/bash.py", line 243, in execute
    raise AirflowException(
airflow.exceptions.AirflowException: Bash command failed. The command returned a non-zero exit code 1.
[2025-07-15T11:03:32.698+0000] {taskinstance.py:1206} INFO - Marking task as FAILED. dag_id=run_dbt_models, task_id=ingest_data, run_id=manual__2025-07-15T10:50:45.194882+00:00, execution_date=20250715T105045, start_date=20250715T110320, end_date=20250715T110332
[2025-07-15T11:03:32.709+0000] {standard_task_runner.py:110} ERROR - Failed to execute job 20 for task ingest_data (Bash command failed. The command returned a non-zero exit code 1.; 2833)
[2025-07-15T11:03:32.750+0000] {local_task_job_runner.py:240} INFO - Task exited with return code 1
[2025-07-15T11:03:32.764+0000] {taskinstance.py:3498} INFO - 0 downstream tasks scheduled from follow-on schedule check
[2025-07-15T11:03:32.774+0000] {local_task_job_runner.py:222} INFO - ::endgroup::
